<?xml version="1.0" encoding="UTF-8"?>
<!-- Generated by org.testng.reporters.JUnitXMLReporter -->
<testsuite hostname="LP-5CD120NLR8" ignored="1" name="Default test" tests="2" failures="1" timestamp="07 Oct 2021 07:27:46 GMT" time="0.052" errors="0">
  <testcase name="second" time="0.031" classname="example.TestNg_Other"/>
  <testcase name="third" time="0.001" classname="example.TestNg_Other">
    <failure type="org.testng.TestException" message="
Method TestNg_Other.third()[pri:0, instance:example.TestNg_Other@2344fc66] should have thrown an exception of type class java.lang.ArithmeticException">
      <![CDATA[org.testng.TestException: 
Method TestNg_Other.third()[pri:0, instance:example.TestNg_Other@2344fc66] should have thrown an exception of type class java.lang.ArithmeticException
	at org.testng.internal.ExpectedExceptionsHolder.noException(ExpectedExceptionsHolder.java:89)
	at org.testng.internal.Invoker.handleInvocationResults(Invoker.java:1416)
	at org.testng.internal.Invoker.invokeMethod(Invoker.java:695)
	at org.testng.internal.Invoker.invokeTestMethod(Invoker.java:869)
	at org.testng.internal.Invoker.invokeTestMethods(Invoker.java:1193)
	at org.testng.internal.TestMethodWorker.invokeTestMethods(TestMethodWorker.java:126)
	at org.testng.internal.TestMethodWorker.run(TestMethodWorker.java:109)
	at org.testng.TestRunner.privateRun(TestRunner.java:744)
	at org.testng.TestRunner.run(TestRunner.java:602)
	at org.testng.SuiteRunner.runTest(SuiteRunner.java:380)
	at org.testng.SuiteRunner.runSequentially(SuiteRunner.java:375)
	at org.testng.SuiteRunner.privateRun(SuiteRunner.java:340)
	at org.testng.SuiteRunner.run(SuiteRunner.java:289)
	at org.testng.SuiteRunnerWorker.runSuite(SuiteRunnerWorker.java:52)
	at org.testng.SuiteRunnerWorker.run(SuiteRunnerWorker.java:86)
	at org.testng.TestNG.runSuitesSequentially(TestNG.java:1301)
	at org.testng.TestNG.runSuitesLocally(TestNG.java:1226)
	at org.testng.TestNG.runSuites(TestNG.java:1144)
	at org.testng.TestNG.run(TestNG.java:1115)
	at org.testng.remote.AbstractRemoteTestNG.run(AbstractRemoteTestNG.java:132)
	at org.testng.remote.RemoteTestNG.initAndRun(RemoteTestNG.java:230)
	at org.testng.remote.RemoteTestNG.main(RemoteTestNG.java:76)
]]>
    </failure>
  </testcase> <!-- third -->
  <testcase name="first" time="0.0" classname="example.TestNg_Other">
    <ignored/>
  </testcase> <!-- first -->
</testsuite> <!-- Default test -->
